Workbook
Name OLE_LINK1: 'Sheet 1. Introduction'!$V$29

Sheet Sheet 1. Introduction

Sheet Sheet 2. County Level Data
A1: County Name(a) | B1: State | C1: Total Population | D1: Rural Population | E1: RUCC | F1: Poverty Population | G1: SVI(c) | H1: Need Measure(b)
P3: Funding Allotment (in dollars)
P4: 10000000
P7: Number of Counties
P8: =COUNTA(A2:A300) -> 0
S10: Number of Formula Items | T10: Floor
P11: Carveout Allotment | S11: Two | T11: =(0.5*P4)/P8 -> #DIV/0!
P12: =P4*'Formula Calculations (LOCKED)'!S2 -> #DIV/0! | S12: Three | T12: =(0.3333333333333*P4)/P8 -> #DIV/0!
S13: Four | T13: =0.25*P4/P8 -> #DIV/0!

Sheet Sheet 3. Total Amounts 
B1: 0: Control Formulas | G1: 1: No Carveout | L1: 2: Rural Carveout
A2: Formula | B2: 0.1 | C2: 0.2 | D2: 0.3 | E2: 0.4 | F2: 0.5 | G2: 1.1 | H2: 1.2 | I2: 1.3 | J2: 1.4 | K2: 1.5 | L2: 2.1 | M2: 2.2 | N2: 2.3
A3: County | B3: Percent population only | C3: Poverty population only | D3: SVI only | E3: Pop 18 and under only | F3: Rural population only | G3: Povery pop +Floor | H3: Poverty pop + Rurality | I3: Poverty pop + Floor + Rurality | J3: Poverty Pop + Floor + Rurality + SVI | K3: Poverty Pop + Floor + Rurality + Pop 18 and under | L3: Carveout + Poverty Pop | M3: Carveout + Poverty + SVI | N3: Carveout + Poverty + Measure of Need
A4: ='Sheet 2. County Level Data'!A2 -> 0 | B4: =('Formula Calculations (LOCKED)'!C4*'Sheet 2. County Level Data'!$P$4) -> #DIV/0! | C4: ='Formula Calculations (LOCKED)'!H4/'Formula Calculations (LOCKED)'!$H$2*'Sheet 2. County Level Data'!$P$4 -> #DIV/0! | D4: =('Formula Calculations (LOCKED)'!L4/'Formula Calculations (LOCKED)'!$L$2)*'Sheet 2. County Level Data'!$P$4 -> #DIV/0! | E4: =('Formula Calculations (LOCKED)'!O4/'Formula Calculations (LOCKED)'!$O$2)*'Sheet 2. County Level Data'!$P$4 -> #DIV/0! | F4: =('Formula Calculations (LOCKED)'!D4/'Formula Calculations (LOCKED)'!$D$2)*'Sheet 2. County Level Data'!$P$4 -> #DIV/0! | G4: ='Sheet 2. County Level Data'!$T$11+(0.5*10000000)*'Formula Calculations (LOCKED)'!H4/'Formula Calculations (LOCKED)'!$H$2 -> #DIV/0! | H4: =(0.5*10000000)*'Formula Calculations (LOCKED)'!H4/'Formula Calculations (LOCKED)'!$H$2+(0.5*10000000)*'Formula Calculations (LOCKED)'!D4/'Formula Calculations (LOCKED)'!$D$2 -> #DIV/0! | I4: ='Sheet 2. County Level Data'!$T$12+(0.3333333333*10000000*('Formula Calculations (LOCKED)'!H4/'Formula Calculations (LOCKED)'!$H$2))+(0.3333333333*10000000*('Formula Calculations (LOCKED)'!D4/'Formula Calculations (LOCKED)'!$D$2)) -> #DIV/0! | J4: ='Sheet 2. County Level Data'!$T$13+(0.25*10000000*('Formula Calculations (LOCKED)'!H4/'Formula Calculations (LOCKED)'!$H$2))+(0.25*10000000*('Formula Calculations (LOCKED)'!D4/'Formula Calculations (LOCKED)'!$D$2))+(0.25*10000000*('Formula Calculations (LOCKED)'!L4/'Formula Calculations (LOCKED)'!$L$2)) -> #DIV/0! | K4: ='Sheet 2. County Level Data'!$T$13+(0.25*10000000*('Formula Calculations (LOCKED)'!H4/'Formula Calculations (LOCKED)'!$H$2))+(0.25*10000000*('Formula Calculations (LOCKED)'!D4/'Formula Calculations (LOCKED)'!$D$2))+(0.25*10000000*('Formula Calculations (LOCKED)'!O4/'Formula Calculations (LOCKED)'!$O$2)) -> #DIV/0! | L4: =IF('Formula Calculations (LOCKED)'!$G4=1,('Sheet 2. County Level Data'!$P$12*('Formula Calculations (LOCKED)'!K4/'Formula Calculations (LOCKED)'!$K$2)),((10000000-'Sheet 2. County Level Data'!$P$12)*'Formula Calculations (LOCKED)'!J4/'Formula Calculations (LOCKED)'!$J$2)) -> #DIV/0! | M4: =IF('Formula Calculations (LOCKED)'!$G4=1,((0.5*'Sheet 2. County Level Data'!$P$12)*('Formula Calculations (LOCKED)'!K4/'Formula Calculations (LOCKED)'!$K$2))+((0.5*'Sheet 2. County Level Data'!$P$12)*('Formula Calculations (LOCKED)'!N4/'Formula Calculations (LOCKED)'!$N$2)),((0.5*(10000000-'Sheet 2. County Level Data'!$P$12))*('Formula Calculations (LOCKED)'!J4/'Formula Calculations (LOCKED)'!$J$2))+((0.5*(10000000-'Sheet 2. County Level Data'!$P$12))*('Formula Calculations (LOCKED)'!M4/'Formula Calculations (LOCKED)'!$M$2))) -> #DIV/0! | N4: =IF('Formula Calculations (LOCKED)'!$G4=1,((0.5*'Sheet 2. County Level Data'!$P$12)*('Formula Calculations (LOCKED)'!K4/'Formula Calculations (LOCKED)'!$K$2))+((0.5*'Sheet 2. County Level Data'!$P$12)*('Formula Calculations (LOCKED)'!R4/'Formula Calculations (LOCKED)'!$R$2)),((0.5*(10000000-'Sheet 2. County Level Data'!$P$12))*('Formula Calculations (LOCKED)'!J4/'Formula Calculations (LOCKED)'!$J$2))+((0.5*(10000000-'Sheet 2. County Level Data'!$P$12))*('Formula Calculations (LOCKED)'!Q4/'Formula Calculations (LOCKED)'!$Q$2))) -> #DIV/0!
A5: ='Sheet 2. County Level Data'!A3 -> 0 | B5: =('Formula Calculations (LOCKED)'!C5*'Sheet 2. County Level Data'!$P$4) -> #DIV/0! | C5: ='Formula Calculations (LOCKED)'!H5/'Formula Calculations (LOCKED)'!$H$2*'Sheet 2. County Level Data'!$P$4 -> #DIV/0! | D5: =('Formula Calculations (LOCKED)'!L5/'Formula Calculations (LOCKED)'!$L$2)*'Sheet 2. County Level Data'!$P$4 -> #DIV/0! | E5: =('Formula Calculations (LOCKED)'!O5/'Formula Calculations (LOCKED)'!$O$2)*'Sheet 2. County Level Data'!$P$4 -> #DIV/0! | F5: =('Formula Calculations (LOCKED)'!D5/'Formula Calculations (LOCKED)'!$D$2)*'Sheet 2. County Level Data'!$P$4 -> #DIV/0! | G5: ='Sheet 2. County Level Data'!$T$11+(0.5*10000000)*'Formula Calculations (LOCKED)'!H5/'Formula Calculations (LOCKED)'!$H$2 -> #DIV/0! | H5: =(0.5*10000000)*'Formula Calculations (LOCKED)'!H5/'Formula Calculations (LOCKED)'!$H$2+(0.5*10000000)*'Formula Calculations (LOCKED)'!D5/'Formula Calculations (LOCKED)'!$D$2 -> #DIV/0! | I5: ='Sheet 2. County Level Data'!$T$12+(0.3333333333*10000000*('Formula Calculations (LOCKED)'!H5/'Formula Calculations (LOCKED)'!$H$2))+(0.3333333333*10000000*('Formula Calculations (LOCKED)'!D5/'Formula Calculations (LOCKED)'!$D$2)) -> #DIV/0! | J5: ='Sheet 2. County Level Data'!$T$13+(0.25*10000000*('Formula Calculations (LOCKED)'!H5/'Formula Calculations (LOCKED)'!$H$2))+(0.25*10000000*('Formula Calculations (LOCKED)'!D5/'Formula Calculations (LOCKED)'!$D$2))+(0.25*10000000*('Formula Calculations (LOCKED)'!L5/'Formula Calculations (LOCKED)'!$L$2)) -> #DIV/0! | K5: ='Sheet 2. County Level Data'!$T$13+(0.25*10000000*('Formula Calculations (LOCKED)'!H5/'Formula Calculations (LOCKED)'!$H$2))+(0.25*10000000*('Formula Calculations (LOCKED)'!D5/'Formula Calculations (LOCKED)'!$D$2))+(0.25*10000000*('Formula Calculations (LOCKED)'!O5/'Formula Calculations (LOCKED)'!$O$2)) -> #DIV/0! | L5: =IF('Formula Calculations (LOCKED)'!$G5=1,('Sheet 2. County Level Data'!$P$12*('Formula Calculations (LOCKED)'!K5/'Formula Calculations (LOCKED)'!$K$2)),((10000000-'Sheet 2. County Level Data'!$P$12)*'Formula Calculations (LOCKED)'!J5/'Formula Calculations (LOCKED)'!$J$2)) -> #DIV/0! | M5: =IF('Formula Calculations (LOCKED)'!$G5=1,((0.5*'Sheet 2. County Level Data'!$P$12)*('Formula Calculations (LOCKED)'!K5/'Formula Calculations (LOCKED)'!$K$2))+((0.5*'Sheet 2. County Level Data'!$P$12)*('Formula Calculations (LOCKED)'!N5/'Formula Calculations (LOCKED)'!$N$2)),((0.5*(10000000-'Sheet 2. County Level Data'!$P$12))*('Formula Calculations (LOCKED)'!J5/'Formula Calculations (LOCKED)'!$J$2))+((0.5*(10000000-'Sheet 2. County Level Data'!$P$12))*('Formula Calculations (LOCKED)'!M5/'Formula Calculations (LOCKED)'!$M$2))) -> #DIV/0! | N5: =IF('Formula Calculations (LOCKED)'!$G5=1,((0.5*'Sheet 2. County Level Data'!$P$12)*('Formula Calculations (LOCKED)'!K5/'Formula Calculations (LOCKED)'!$K$2))+((0.5*'Sheet 2. County Level Data'!$P$12)*('Formula Calculations (LOCKED)'!R5/'Formula Calculations (LOCKED)'!$R$2)),((0.5*(10000000-'Sheet 2. County Level Data'!$P$12))*('Formula Calculations (LOCKED)'!J5/'Formula Calculations (LOCKED)'!$J$2))+((0.5*(10000000-'Sheet 2. County Level Data'!$P$12))*('Formula Calculations (LOCKED)'!Q5/'Formula Calculations (LOCKED)'!$Q$2))) -> #DIV/0!
A6: ='Sheet 2. County Level Data'!A4 -> 0 | B6: =('Formula Calculations (LOCKED)'!C6*'Sheet 2. County Level Data'!$P$4) -> #DIV/0! | C6: ='Formula Calculations (LOCKED)'!H6/'Formula Calculations (LOCKED)'!$H$2*'Sheet 2. County Level Data'!$P$4 -> #DIV/0! | D6: =('Formula Calculations (LOCKED)'!L6/'Formula Calculations (LOCKED)'!$L$2)*'Sheet 2. County Level Data'!$P$4 -> #DIV/0! | E6: =('Formula Calculations (LOCKED)'!O6/'Formula Calculations (LOCKED)'!$O$2)*'Sheet 2. County Level Data'!$P$4 -> #DIV/0! | F6: =('Formula Calculations (LOCKED)'!D6/'Formula Calculations (LOCKED)'!$D$2)*'Sheet 2. County Level Data'!$P$4 -> #DIV/0! | G6: ='Sheet 2. County Level Data'!$T$11+(0.5*10000000)*'Formula Calculations (LOCKED)'!H6/'Formula Calculations (LOCKED)'!$H$2 -> #DIV/0! | H6: =(0.5*10000000)*'Formula Calculations (LOCKED)'!H6/'Formula Calculations (LOCKED)'!$H$2+(0.5*10000000)*'Formula Calculations (LOCKED)'!D6/'Formula Calculations (LOCKED)'!$D$2 -> #DIV/0! | I6: ='Sheet 2. County Level Data'!$T$12+(0.3333333333*10000000*('Formula Calculations (LOCKED)'!H6/'Formula Calculations (LOCKED)'!$H$2))+(0.3333333333*10000000*('Formula Calculations (LOCKED)'!D6/'Formula Calculations (LOCKED)'!$D$2)) -> #DIV/0! | J6: ='Sheet 2. County Level Data'!$T$13+(0.25*10000000*('Formula Calculations (LOCKED)'!H6/'Formula Calculations (LOCKED)'!$H$2))+(0.25*10000000*('Formula Calculations (LOCKED)'!D6/'Formula Calculations (LOCKED)'!$D$2))+(0.25*10000000*('Formula Calculations (LOCKED)'!L6/'Formula Calculations (LOCKED)'!$L$2)) -> #DIV/0! | K6: ='Sheet 2. County Level Data'!$T$13+(0.25*10000000*('Formula Calculations (LOCKED)'!H6/'Formula Calculations (LOCKED)'!$H$2))+(0.25*10000000*('Formula Calculations (LOCKED)'!D6/'Formula Calculations (LOCKED)'!$D$2))+(0.25*10000000*('Formula Calculations (LOCKED)'!O6/'Formula Calculations (LOCKED)'!$O$2)) -> #DIV/0! | L6: =IF('Formula Calculations (LOCKED)'!$G6=1,('Sheet 2. County Level Data'!$P$12*('Formula Calculations (LOCKED)'!K6/'Formula Calculations (LOCKED)'!$K$2)),((10000000-'Sheet 2. County Level Data'!$P$12)*'Formula Calculations (LOCKED)'!J6/'Formula Calculations (LOCKED)'!$J$2)) -> #DIV/0! | M6: =IF('Formula Calculations (LOCKED)'!$G6=1,((0.5*'Sheet 2. County Level Data'!$P$12)*('Formula Calculations (LOCKED)'!K6/'Formula Calculations (LOCKED)'!$K$2))+((0.5*'Sheet 2. County Level Data'!$P$12)*('Formula Calculations (LOCKED)'!N6/'Formula Calculations (LOCKED)'!$N$2)),((0.5*(10000000-'Sheet 2. County Level Data'!$P$12))*('Formula Calculations (LOCKED)'!J6/'Formula Calculations (LOCKED)'!$J$2))+((0.5*(10000000-'Sheet 2. County Level Data'!$P$12))*('Formula Calculations (LOCKED)'!M6/'Formula Calculations (LOCKED)'!$M$2))) -> #DIV/0! | N6: =IF('Formula Calculations (LOCKED)'!$G6=1,((0.5*'Sheet 2. County Level Data'!$P$12)*('Formula Calculations (LOCKED)'!K6/'Formula Calculations (LOCKED)'!$K$2))+((0.5*'Sheet 2. County Level Data'!$P$12)*('Formula Calculations (LOCKED)'!R6/'Formula Calculations (LOCKED)'!$R$2)),((0.5*(10000000-'Sheet 2. County Level Data'!$P$12))*('Formula Calculations (LOCKED)'!J6/'Formula Calculations (LOCKED)'!$J$2))+((0.5*(10000000-'Sheet 2. County Level Data'!$P$12))*('Formula Calculations (LOCKED)'!Q6/'Formula Calculations (LOCKED)'!$Q$2))) -> #DIV/0!
A7: ='Sheet 2. County Level Data'!A5 -> 0 | B7: =('Formula Calculations (LOCKED)'!C7*'Sheet 2. County Level Data'!$P$4) -> #DIV/0! | C7: ='Formula Calculations (LOCKED)'!H7/'Formula Calculations (LOCKED)'!$H$2*'Sheet 2. County Level Data'!$P$4 -> #DIV/0! | D7: =('Formula Calculations (LOCKED)'!L7/'Formula Calculations (LOCKED)'!$L$2)*'Sheet 2. County Level Data'!$P$4 -> #DIV/0! | E7: =('Formula Calculations (LOCKED)'!O7/'Formula Calculations (LOCKED)'!$O$2)*'Sheet 2. County Level Data'!$P$4 -> #DIV/0! | F7: =('Formula Calculations (LOCKED)'!D7/'Formula Calculations (LOCKED)'!$D$2)*'Sheet 2. County Level Data'!$P$4 -> #DIV/0! | G7: ='Sheet 2. County Level Data'!$T$11+(0.5*10000000)*'Formula Calculations (LOCKED)'!H7/'Formula Calculations (LOCKED)'!$H$2 -> #DIV/0! | H7: =(0.5*10000000)*'Formula Calculations (LOCKED)'!H7/'Formula Calculations (LOCKED)'!$H$2+(0.5*10000000)*'Formula Calculations (LOCKED)'!D7/'Formula Calculations (LOCKED)'!$D$2 -> #DIV/0! | I7: ='Sheet 2. County Level Data'!$T$12+(0.3333333333*10000000*('Formula Calculations (LOCKED)'!H7/'Formula Calculations (LOCKED)'!$H$2))+(0.3333333333*10000000*('Formula Calculations (LOCKED)'!D7/'Formula Calculations (LOCKED)'!$D$2)) -> #DIV/0! | J7: ='Sheet 2. County Level Data'!$T$13+(0.25*10000000*('Formula Calculations (LOCKED)'!H7/'Formula Calculations (LOCKED)'!$H$2))+(0.25*10000000*('Formula Calculations (LOCKED)'!D7/'Formula Calculations (LOCKED)'!$D$2))+(0.25*10000000*('Formula Calculations (LOCKED)'!L7/'Formula Calculations (LOCKED)'!$L$2)) -> #DIV/0! | K7: ='Sheet 2. County Level Data'!$T$13+(0.25*10000000*('Formula Calculations (LOCKED)'!H7/'Formula Calculations (LOCKED)'!$H$2))+(0.25*10000000*('Formula Calculations (LOCKED)'!D7/'Formula Calculations (LOCKED)'!$D$2))+(0.25*10000000*('Formula Calculations (LOCKED)'!O7/'Formula Calculations (LOCKED)'!$O$2)) -> #DIV/0! | L7: =IF('Formula Calculations (LOCKED)'!$G7=1,('Sheet 2. County Level Data'!$P$12*('Formula Calculations (LOCKED)'!K7/'Formula Calculations (LOCKED)'!$K$2)),((10000000-'Sheet 2. County Level Data'!$P$12)*'Formula Calculations (LOCKED)'!J7/'Formula Calculations (LOCKED)'!$J$2)) -> #DIV/0! | M7: =IF('Formula Calculations (LOCKED)'!$G7=1,((0.5*'Sheet 2. County Level Data'!$P$12)*('Formula Calculations (LOCKED)'!K7/'Formula Calculations (LOCKED)'!$K$2))+((0.5*'Sheet 2. County Level Data'!$P$12)*('Formula Calculations (LOCKED)'!N7/'Formula Calculations (LOCKED)'!$N$2)),((0.5*(10000000-'Sheet 2. County Level Data'!$P$12))*('Formula Calculations (LOCKED)'!J7/'Formula Calculations (LOCKED)'!$J$2))+((0.5*(10000000-'Sheet 2. County Level Data'!$P$12))*('Formula Calculations (LOCKED)'!M7/'Formula Calculations (LOCKED)'!$M$2))) -> #DIV/0! | N7: =IF('Formula Calculations (LOCKED)'!$G7=1,((0.5*'Sheet 2. County Level Data'!$P$12)*('Formula Calculations (LOCKED)'!K7/'Formula Calculations (LOCKED)'!$K$2))+((0.5*'Sheet 2. County Level Data'!$P$12)*('Formula Calculations (LOCKED)'!R7/'Formula Calculations (LOCKED)'!$R$2)),((0.5*(10000000-'Sheet 2. County Level Data'!$P$12))*('Formula Calculations (LOCKED)'!J7/'Formula Calculations (LOCKED)'!$J$2))+((0.5*(10000000-'Sheet 2. County Level Data'!$P$12))*('Formula Calculations (LOCKED)'!Q7/'Formula Calculations (LOCKED)'!$Q$2))) -> #DIV/0!
A8: ='Sheet 2. County Level Data'!A6 -> 0 | B8: =('Formula Calculations (LOCKED)'!C8*'Sheet 2. County Level Data'!$P$4) -> #DIV/0! | C8: ='Formula Calculations (LOCKED)'!H8/'Formula Calculations (LOCKED)'!$H$2*'Sheet 2. County Level Data'!$P$4 -> #DIV/0! | D8: =('Formula Calculations (LOCKED)'!L8/'Formula Calculations (LOCKED)'!$L$2)*'Sheet 2. County Level Data'!$P$4 -> #DIV/0! | E8: =('Formula Calculations (LOCKED)'!O8/'Formula Calculations (LOCKED)'!$O$2)*'Sheet 2. County Level Data'!$P$4 -> #DIV/0! | F8: =('Formula Calculations (LOCKED)'!D8/'Formula Calculations (LOCKED)'!$D$2)*'Sheet 2. County Level Data'!$P$4 -> #DIV/0! | G8: ='Sheet 2. County Level Data'!$T$11+(0.5*10000000)*'Formula Calculations (LOCKED)'!H8/'Formula Calculations (LOCKED)'!$H$2 -> #DIV/0! | H8: =(0.5*10000000)*'Formula Calculations (LOCKED)'!H8/'Formula Calculations (LOCKED)'!$H$2+(0.5*10000000)*'Formula Calculations (LOCKED)'!D8/'Formula Calculations (LOCKED)'!$D$2 -> #DIV/0! | I8: ='Sheet 2. County Level Data'!$T$12+(0.3333333333*10000000*('Formula Calculations (LOCKED)'!H8/'Formula Calculations (LOCKED)'!$H$2))+(0.3333333333*10000000*('Formula Calculations (LOCKED)'!D8/'Formula Calculations (LOCKED)'!$D$2)) -> #DIV/0! | J8: ='Sheet 2. County Level Data'!$T$13+(0.25*10000000*('Formula Calculations (LOCKED)'!H8/'Formula Calculations (LOCKED)'!$H$2))+(0.25*10000000*('Formula Calculations (LOCKED)'!D8/'Formula Calculations (LOCKED)'!$D$2))+(0.25*10000000*('Formula Calculations (LOCKED)'!L8/'Formula Calculations (LOCKED)'!$L$2)) -> #DIV/0! | K8: ='Sheet 2. County Level Data'!$T$13+(0.25*10000000*('Formula Calculations (LOCKED)'!H8/'Formula Calculations (LOCKED)'!$H$2))+(0.25*10000000*('Formula Calculations (LOCKED)'!D8/'Formula Calculations (LOCKED)'!$D$2))+(0.25*10000000*('Formula Calculations (LOCKED)'!O8/'Formula Calculations (LOCKED)'!$O$2)) -> #DIV/0! | L8: =IF('Formula Calculations (LOCKED)'!$G8=1,('Sheet 2. County Level Data'!$P$12*('Formula Calculations (LOCKED)'!K8/'Formula Calculations (LOCKED)'!$K$2)),((10000000-'Sheet 2. County Level Data'!$P$12)*'Formula Calculations (LOCKED)'!J8/'Formula Calculations (LOCKED)'!$J$2)) -> #DIV/0! | M8: =IF('Formula Calculations (LOCKED)'!$G8=1,((0.5*'Sheet 2. County Level Data'!$P$12)*('Formula Calculations (LOCKED)'!K8/'Formula Calculations (LOCKED)'!$K$2))+((0.5*'Sheet 2. County Level Data'!$P$12)*('Formula Calculations (LOCKED)'!N8/'Formula Calculations (LOCKED)'!$N$2)),((0.5*(10000000-'Sheet 2. County Level Data'!$P$12))*('Formula Calculations (LOCKED)'!J8/'Formula Calculations (LOCKED)'!$J$2))+((0.5*(10000000-'Sheet 2. County Level Data'!$P$12))*('Formula Calculations (LOCKED)'!M8/'Formula Calculations (LOCKED)'!$M$2))) -> #DIV/0! | N8: =IF('Formula Calculations (LOCKED)'!$G8=1,((0.5*'Sheet 2. County Level Data'!$P$12)*('Formula Calculations (LOCKED)'!K8/'Formula Calculations (LOCKED)'!$K$2))+((0.5*'Sheet 2. County Level Data'!$P$12)*('Formula Calculations (LOCKED)'!R8/'Formula Calculations (LOCKED)'!$R$2)),((0.5*(10000000-'Sheet 2. County Level Data'!$P$12))*('Formula Calculations (LOCKED)'!J8/'Formula Calculations (LOCKED)'!$J$2))+((0.5*(10000000-'Sheet 2. County Level Data'!$P$12))*('Formula Calculations (LOCKED)'!Q8/'Formula Calculations (LOCKED)'!$Q$2))) -> #DIV/0!
A9: ='Sheet 2. County Level Data'!A7 -> 0 | B9: =('Formula Calculations (LOCKED)'!C9*'Sheet 2. County Level Data'!$P$4) -> #DIV/0! | C9: ='Formula Calculations (LOCKED)'!H9/'Formula Calculations (LOCKED)'!$H$2*'Sheet 2. County Level Data'!$P$4 -> #DIV/0! | D9: =('Formula Calculations (LOCKED)'!L9/'Formula Calculations (LOCKED)'!$L$2)*'Sheet 2. County Level Data'!$P$4 -> #DIV/0! | E9: =('Formula Calculations (LOCKED)'!O9/'Formula Calculations (LOCKED)'!$O$2)*'Sheet 2. County Level Data'!$P$4 -> #DIV/0! | F9: =('Formula Calculations (LOCKED)'!D9/'Formula Calculations (LOCKED)'!$D$2)*'Sheet 2. County Level Data'!$P$4 -> #DIV/0! | G9: ='Sheet 2. County Level Data'!$T$11+(0.5*10000000)*'Formula Calculations (LOCKED)'!H9/'Formula Calculations (LOCKED)'!$H$2 -> #DIV/0! | H9: =(0.5*10000000)*'Formula Calculations (LOCKED)'!H9/'Formula Calculations (LOCKED)'!$H$2+(0.5*10000000)*'Formula Calculations (LOCKED)'!D9/'Formula Calculations (LOCKED)'!$D$2 -> #DIV/0! | I9: ='Sheet 2. County Level Data'!$T$12+(0.3333333333*10000000*('Formula Calculations (LOCKED)'!H9/'Formula Calculations (LOCKED)'!$H$2))+(0.3333333333*10000000*('Formula Calculations (LOCKED)'!D9/'Formula Calculations (LOCKED)'!$D$2)) -> #DIV/0! | J9: ='Sheet 2. County Level Data'!$T$13+(0.25*10000000*('Formula Calculations (LOCKED)'!H9/'Formula Calculations (LOCKED)'!$H$2))+(0.25*10000000*('Formula Calculations (LOCKED)'!D9/'Formula Calculations (LOCKED)'!$D$2))+(0.25*10000000*('Formula Calculations (LOCKED)'!L9/'Formula Calculations (LOCKED)'!$L$2)) -> #DIV/0! | K9: ='Sheet 2. County Level Data'!$T$13+(0.25*10000000*('Formula Calculations (LOCKED)'!H9/'Formula Calculations (LOCKED)'!$H$2))+(0.25*10000000*('Formula Calculations (LOCKED)'!D9/'Formula Calculations (LOCKED)'!$D$2))+(0.25*10000000*('Formula Calculations (LOCKED)'!O9/'Formula Calculations (LOCKED)'!$O$2)) -> #DIV/0! | L9: =IF('Formula Calculations (LOCKED)'!$G9=1,('Sheet 2. County Level Data'!$P$12*('Formula Calculations (LOCKED)'!K9/'Formula Calculations (LOCKED)'!$K$2)),((10000000-'Sheet 2. County Level Data'!$P$12)*'Formula Calculations (LOCKED)'!J9/'Formula Calculations (LOCKED)'!$J$2)) -> #DIV/0! | M9: =IF('Formula Calculations (LOCKED)'!$G9=1,((0.5*'Sheet 2. County Level Data'!$P$12)*('Formula Calculations (LOCKED)'!K9/'Formula Calculations (LOCKED)'!$K$2))+((0.5*'Sheet 2. County Level Data'!$P$12)*('Formula Calculations (LOCKED)'!N9/'Formula Calculations (LOCKED)'!$N$2)),((0.5*(10000000-'Sheet 2. County Level Data'!$P$12))*('Formula Calculations (LOCKED)'!J9/'Formula Calculations (LOCKED)'!$J$2))+((0.5*(10000000-'Sheet 2. County Level Data'!$P$12))*('Formula Calculations (LOCKED)'!M9/'Formula Calculations (LOCKED)'!$M$2))) -> #DIV/0! | N9: =IF('Formula Calculations (LOCKED)'!$G9=1,((0.5*'Sheet 2. County Level Data'!$P$12)*('Formula Calculations (LOCKED)'!K9/'Formula Calculations (LOCKED)'!$K$2))+((0.5*'Sheet 2. County Level Data'!$P$12)*('Formula Calculations (LOCKED)'!R9/'Formula Calculations (LOCKED)'!$R$2)),((0.5*(10000000-'Sheet 2. County Level Data'!$P$12))*('Formula Calculations (LOCKED)'!J9/'Formula Calculations (LOCKED)'!$J$2))+((0.5*(10000000-'Sheet 2. County Level Data'!$P$12))*('Formula Calculations (LOCKED)'!Q9/'Formula Calculations (LOCKED)'!$Q$2))) -> #DIV/0!
A10: ='Sheet 2. County Level Data'!A8 -> 0 | B10: =('Formula Calculations (LOCKED)'!C10*'Sheet 2. County Level Data'!$P$4) -> #DIV/0! | C10: ='Formula Calculations (LOCKED)'!H10/'Formula Calculations (LOCKED)'!$H$2*'Sheet 2. County Level Data'!$P$4 -> #DIV/0! | D10: =('Formula Calculations (LOCKED)'!L10/'Formula Calculations (LOCKED)'!$L$2)*'Sheet 2. County Level Data'!$P$4 -> #DIV/0! | E10: =('Formula Calculations (LOCKED)'!O10/'Formula Calculations (LOCKED)'!$O$2)*'Sheet 2. County Level Data'!$P$4 -> #DIV/0! | F10: =('Formula Calculations (LOCKED)'!D10/'Formula Calculations (LOCKED)'!$D$2)*'Sheet 2. County Level Data'!$P$4 -> #DIV/0! | G10: ='Sheet 2. County Level Data'!$T$11+(0.5*10000000)*'Formula Calculations (LOCKED)'!H10/'Formula Calculations (LOCKED)'!$H$2 -> #DIV/0! | H10: =(0.5*10000000)*'Formula Calculations (LOCKED)'!H10/'Formula Calculations (LOCKED)'!$H$2+(0.5*10000000)*'Formula Calculations (LOCKED)'!D10/'Formula Calculations (LOCKED)'!$D$2 -> #DIV/0! | I10: ='Sheet 2. County Level Data'!$T$12+(0.3333333333*10000000*('Formula Calculations (LOCKED)'!H10/'Formula Calculations (LOCKED)'!$H$2))+(0.3333333333*10000000*('Formula Calculations (LOCKED)'!D10/'Formula Calculations (LOCKED)'!$D$2)) -> #DIV/0! | J10: ='Sheet 2. County Level Data'!$T$13+(0.25*10000000*('Formula Calculations (LOCKED)'!H10/'Formula Calculations (LOCKED)'!$H$2))+(0.25*10000000*('Formula Calculations (LOCKED)'!D10/'Formula Calculations (LOCKED)'!$D$2))+(0.25*10000000*('Formula Calculations (LOCKED)'!L10/'Formula Calculations (LOCKED)'!$L$2)) -> #DIV/0! | K10: ='Sheet 2. County Level Data'!$T$13+(0.25*10000000*('Formula Calculations (LOCKED)'!H10/'Formula Calculations (LOCKED)'!$H$2))+(0.25*10000000*('Formula Calculations (LOCKED)'!D10/'Formula Calculations (LOCKED)'!$D$2))+(0.25*10000000*('Formula Calculations (LOCKED)'!O10/'Formula Calculations (LOCKED)'!$O$2)) -> #DIV/0! | L10: =IF('Formula Calculations (LOCKED)'!$G10=1,('Sheet 2. County Level Data'!$P$12*('Formula Calculations (LOCKED)'!K10/'Formula Calculations (LOCKED)'!$K$2)),((10000000-'Sheet 2. County Level Data'!$P$12)*'Formula Calculations (LOCKED)'!J10/'Formula Calculations (LOCKED)'!$J$2)) -> #DIV/0! | M10: =IF('Formula Calculations (LOCKED)'!$G10=1,((0.5*'Sheet 2. County Level Data'!$P$12)*('Formula Calculations (LOCKED)'!K10/'Formula Calculations (LOCKED)'!$K$2))+((0.5*'Sheet 2. County Level Data'!$P$12)*('Formula Calculations (LOCKED)'!N10/'Formula Calculations (LOCKED)'!$N$2)),((0.5*(10000000-'Sheet 2. County Level Data'!$P$12))*('Formula Calculations (LOCKED)'!J10/'Formula Calculations (LOCKED)'!$J$2))+((0.5*(10000000-'Sheet 2. County Level Data'!$P$12))*('Formula Calculations (LOCKED)'!M10/'Formula Calculations (LOCKED)'!$M$2))) -> #DIV/0! | N10: =IF('Formula Calculations (LOCKED)'!$G10=1,((0.5*'Sheet 2. County Level Data'!$P$12)*('Formula Calculations (LOCKED)'!K10/'Formula Calculations (LOCKED)'!$K$2))+((0.5*'Sheet 2. County Level Data'!$P$12)*('Formula Calculations (LOCKED)'!R10/'Formula Calculations (LOCKED)'!$R$2)),((0.5*(10000000-'Sheet 2. County Level Data'!$P$12))*('Formula Calculations (LOCKED)'!J10/'Formula Calculations (LOCKED)'!$J$2))+((0.5*(10000000-'Sheet 2. County Level Data'!$P$12))*('Formula Calculations (LOCKED)'!Q10/'Formula Calculations (LOCKED)'!$Q$2))) -> #DIV/0!
A11: ='Sheet 2. County Level Data'!A9 -> 0 | B11: =('Formula Calculations (LOCKED)'!C11*'Sheet 2. County Level Data'!$P$4) -> #DIV/0! | C11: ='Formula Calculations (LOCKED)'!H11/'Formula Calculations (LOCKED)'!$H$2*'Sheet 2. County Level Data'!$P$4 -> #DIV/0! | D11: =('Formula Calculations (LOCKED)'!L11/'Formula Calculations (LOCKED)'!$L$2)*'Sheet 2. County Level Data'!$P$4 -> #DIV/0! | E11: =('Formula Calculations (LOCKED)'!O11/'Formula Calculations (LOCKED)'!$O$2)*'Sheet 2. County Level Data'!$P$4 -> #DIV/0! | F11: =('Formula Calculations (LOCKED)'!D11/'Formula Calculations (LOCKED)'!$D$2)*'Sheet 2. County Level Data'!$P$4 -> #DIV/0! | G11: ='Sheet 2. County Level Data'!$T$11+(0.5*10000000)*'Formula Calculations (LOCKED)'!H11/'Formula Calculations (LOCKED)'!$H$2 -> #DIV/0! | H11: =(0.5*10000000)*'Formula Calculations (LOCKED)'!H11/'Formula Calculations (LOCKED)'!$H$2+(0.5*10000000)*'Formula Calculations (LOCKED)'!D11/'Formula Calculations (LOCKED)'!$D$2 -> #DIV/0! | I11: ='Sheet 2. County Level Data'!$T$12+(0.3333333333*10000000*('Formula Calculations (LOCKED)'!H11/'Formula Calculations (LOCKED)'!$H$2))+(0.3333333333*10000000*('Formula Calculations (LOCKED)'!D11/'Formula Calculations (LOCKED)'!$D$2)) -> #DIV/0! | J11: ='Sheet 2. County Level Data'!$T$13+(0.25*10000000*('Formula Calculations (LOCKED)'!H11/'Formula Calculations (LOCKED)'!$H$2))+(0.25*10000000*('Formula Calculations (LOCKED)'!D11/'Formula Calculations (LOCKED)'!$D$2))+(0.25*10000000*('Formula Calculations (LOCKED)'!L11/'Formula Calculations (LOCKED)'!$L$2)) -> #DIV/0! | K11: ='Sheet 2. County Level Data'!$T$13+(0.25*10000000*('Formula Calculations (LOCKED)'!H11/'Formula Calculations (LOCKED)'!$H$2))+(0.25*10000000*('Formula Calculations (LOCKED)'!D11/'Formula Calculations (LOCKED)'!$D$2))+(0.25*10000000*('Formula Calculations (LOCKED)'!O11/'Formula Calculations (LOCKED)'!$O$2)) -> #DIV/0! | L11: =IF('Formula Calculations (LOCKED)'!$G11=1,('Sheet 2. County Level Data'!$P$12*('Formula Calculations (LOCKED)'!K11/'Formula Calculations (LOCKED)'!$K$2)),((10000000-'Sheet 2. County Level Data'!$P$12)*'Formula Calculations (LOCKED)'!J11/'Formula Calculations (LOCKED)'!$J$2)) -> #DIV/0! | M11: =IF('Formula Calculations (LOCKED)'!$G11=1,((0.5*'Sheet 2. County Level Data'!$P$12)*('Formula Calculations (LOCKED)'!K11/'Formula Calculations (LOCKED)'!$K$2))+((0.5*'Sheet 2. County Level Data'!$P$12)*('Formula Calculations (LOCKED)'!N11/'Formula Calculations (LOCKED)'!$N$2)),((0.5*(10000000-'Sheet 2. County Level Data'!$P$12))*('Formula Calculations (LOCKED)'!J11/'Formula Calculations (LOCKED)'!$J$2))+((0.5*(10000000-'Sheet 2. County Level Data'!$P$12))*('Formula Calculations (LOCKED)'!M11/'Formula Calculations (LOCKED)'!$M$2))) -> #DIV/0! | N11: =IF('Formula Calculations (LOCKED)'!$G11=1,((0.5*'Sheet 2. County Level Data'!$P$12)*('Formula Calculations (LOCKED)'!K11/'Formula Calculations (LOCKED)'!$K$2))+((0.5*'Sheet 2. County Level Data'!$P$12)*('Formula Calculations (LOCKED)'!R11/'Formula Calculations (LOCKED)'!$R$2)),((0.5*(10000000-'Sheet 2. County Level Data'!$P$12))*('Formula Calculations (LOCKED)'!J11/'Formula Calculations (LOCKED)'!$J$2))+((0.5*(10000000-'Sheet 2. County Level Data'!$P$12))*('Formula Calculations (LOCKED)'!Q11/'Formula Calculations (LOCKED)'!$Q$2))) -> #DIV/0!
A12: ='Sheet 2. County Level Data'!A10 -> 0 | B12: =('Formula Calculations (LOCKED)'!C12*'Sheet 2. County Level Data'!$P$4) -> #DIV/0! | C12: ='Formula Calculations (LOCKED)'!H12/'Formula Calculations (LOCKED)'!$H$2*'Sheet 2. County Level Data'!$P$4 -> #DIV/0! | D12: =('Formula Calculations (LOCKED)'!L12/'Formula Calculations (LOCKED)'!$L$2)*'Sheet 2. County Level Data'!$P$4 -> #DIV/0! | E12: =('Formula Calculations (LOCKED)'!O12/'Formula Calculations (LOCKED)'!$O$2)*'Sheet 2. County Level Data'!$P$4 -> #DIV/0! | F12: =('Formula Calculations (LOCKED)'!D12/'Formula Calculations (LOCKED)'!$D$2)*'Sheet 2. County Level Data'!$P$4 -> #DIV/0! | G12: ='Sheet 2. County Level Data'!$T$11+(0.5*10000000)*'Formula Calculations (LOCKED)'!H12/'Formula Calculations (LOCKED)'!$H$2 -> #DIV/0! | H12: =(0.5*10000000)*'Formula Calculations (LOCKED)'!H12/'Formula Calculations (LOCKED)'!$H$2+(0.5*10000000)*'Formula Calculations (LOCKED)'!D12/'Formula Calculations (LOCKED)'!$D$2 -> #DIV/0! | I12: ='Sheet 2. County Level Data'!$T$12+(0.3333333333*10000000*('Formula Calculations (LOCKED)'!H12/'Formula Calculations (LOCKED)'!$H$2))+(0.3333333333*10000000*('Formula Calculations (LOCKED)'!D12/'Formula Calculations (LOCKED)'!$D$2)) -> #DIV/0! | J12: ='Sheet 2. County Level Data'!$T$13+(0.25*10000000*('Formula Calculations (LOCKED)'!H12/'Formula Calculations (LOCKED)'!$H$2))+(0.25*10000000*('Formula Calculations (LOCKED)'!D12/'Formula Calculations (LOCKED)'!$D$2))+(0.25*10000000*('Formula Calculations (LOCKED)'!L12/'Formula Calculations (LOCKED)'!$L$2)) -> #DIV/0! | K12: ='Sheet 2. County Level Data'!$T$13+(0.25*10000000*('Formula Calculations (LOCKED)'!H12/'Formula Calculations (LOCKED)'!$H$2))+(0.25*10000000*('Formula Calculations (LOCKED)'!D12/'Formula Calculations (LOCKED)'!$D$2))+(0.25*10000000*('Formula Calculations (LOCKED)'!O12/'Formula Calculations (LOCKED)'!$O$2)) -> #DIV/0! | L12: =IF('Formula Calculations (LOCKED)'!$G12=1,('Sheet 2. County Level Data'!$P$12*('Formula Calculations (LOCKED)'!K12/'Formula Calculations (LOCKED)'!$K$2)),((10000000-'Sheet 2. County Level Data'!$P$12)*'Formula Calculations (LOCKED)'!J12/'Formula Calculations (LOCKED)'!$J$2)) -> #DIV/0! | M12: =IF('Formula Calculations (LOCKED)'!$G12=1,((0.5*'Sheet 2. County Level Data'!$P$12)*('Formula Calculations (LOCKED)'!K12/'Formula Calculations (LOCKED)'!$K$2))+((0.5*'Sheet 2. County Level Data'!$P$12)*('Formula Calculations (LOCKED)'!N12/'Formula Calculations (LOCKED)'!$N$2)),((0.5*(10000000-'Sheet 2. County Level Data'!$P$12))*('Formula Calculations (LOCKED)'!J12/'Formula Calculations (LOCKED)'!$J$2))+((0.5*(10000000-'Sheet 2. County Level Data'!$P$12))*('Formula Calculations (LOCKED)'!M12/'Formula Calculations (LOCKED)'!$M$2))) -> #DIV/0! | N12: =IF('Formula Calculations (LOCKED)'!$G12=1,((0.5*'Sheet 2. County Level Data'!$P$12)*('Formula Calculations (LOCKED)'!K12/'Formula Calculations (LOCKED)'!$K$2))+((0.5*'Sheet 2. County Level Data'!$P$12)*('Formula Calculations (LOCKED)'!R12/'Formula Calculations (LOCKED)'!$R$2)),((0.5*(10000000-'Sheet 2. County Level Data'!$P$12))*('Formula Calculations (LOCKED)'!J12/'Formula Calculations (LOCKED)'!$J$2))+((0.5*(10000000-'Sheet 2. County Level Data'!$P$12))*('Formula Calculations (LOCKED)'!Q12/'Formula Calculations (LOCKED)'!$Q$2))) -> #DIV/0!
A13: ='Sheet 2. County Level Data'!A11 -> 0 | B13: =('Formula Calculations (LOCKED)'!C13*'Sheet 2. County Level Data'!$P$4) -> #DIV/0! | C13: ='Formula Calculations (LOCKED)'!H13/'Formula Calculations (LOCKED)'!$H$2*'Sheet 2. County Level Data'!$P$4 -> #DIV/0! | D13: =('Formula Calculations (LOCKED)'!L13/'Formula Calculations (LOCKED)'!$L$2)*'Sheet 2. County Level Data'!$P$4 -> #DIV/0! | E13: =('Formula Calculations (LOCKED)'!O13/'Formula Calculations (LOCKED)'!$O$2)*'Sheet 2. County Level Data'!$P$4 -> #DIV/0! | F13: =('Formula Calculations (LOCKED)'!D13/'Formula Calculations (LOCKED)'!$D$2)*'Sheet 2. County Level Data'!$P$4 -> #DIV/0! | G13: ='Sheet 2. County Level Data'!$T$11+(0.5*10000000)*'Formula Calculations (LOCKED)'!H13/'Formula Calculations (LOCKED)'!$H$2 -> #DIV/0! | H13: =(0.5*10000000)*'Formula Calculations (LOCKED)'!H13/'Formula Calculations (LOCKED)'!$H$2+(0.5*10000000)*'Formula Calculations (LOCKED)'!D13/'Formula Calculations (LOCKED)'!$D$2 -> #DIV/0! | I13: ='Sheet 2. County Level Data'!$T$12+(0.3333333333*10000000*('Formula Calculations (LOCKED)'!H13/'Formula Calculations (LOCKED)'!$H$2))+(0.3333333333*10000000*('Formula Calculations (LOCKED)'!D13/'Formula Calculations (LOCKED)'!$D$2)) -> #DIV/0! | J13: ='Sheet 2. County Level Data'!$T$13+(0.25*10000000*('Formula Calculations (LOCKED)'!H13/'Formula Calculations (LOCKED)'!$H$2))+(0.25*10000000*('Formula Calculations (LOCKED)'!D13/'Formula Calculations (LOCKED)'!$D$2))+(0.25*10000000*('Formula Calculations (LOCKED)'!L13/'Formula Calculations (LOCKED)'!$L$2)) -> #DIV/0! | K13: ='Sheet 2. County Level Data'!$T$13+(0.25*10000000*('Formula Calculations (LOCKED)'!H13/'Formula Calculations (LOCKED)'!$H$2))+(0.25*10000000*('Formula Calculations (LOCKED)'!D13/'Formula Calculations (LOCKED)'!$D$2))+(0.25*10000000*('Formula Calculations (LOCKED)'!O13/'Formula Calculations (LOCKED)'!$O$2)) -> #DIV/0! | L13: =IF('Formula Calculations (LOCKED)'!$G13=1,('Sheet 2. County Level Data'!$P$12*('Formula Calculations (LOCKED)'!K13/'Formula Calculations (LOCKED)'!$K$2)),((10000000-'Sheet 2. County Level Data'!$P$12)*'Formula Calculations (LOCKED)'!J13/'Formula Calculations (LOCKED)'!$J$2)) -> #DIV/0! | M13: =IF('Formula Calculations (LOCKED)'!$G13=1,((0.5*'Sheet 2. County Level Data'!$P$12)*('Formula Calculations (LOCKED)'!K13/'Formula Calculations (LOCKED)'!$K$2))+((0.5*'Sheet 2. County Level Data'!$P$12)*('Formula Calculations (LOCKED)'!N13/'Formula Calculations (LOCKED)'!$N$2)),((0.5*(10000000-'Sheet 2. County Level Data'!$P$12))*('Formula Calculations (LOCKED)'!J13/'Formula Calculations (LOCKED)'!$J$2))+((0.5*(10000000-'Sheet 2. County Level Data'!$P$12))*('Formula Calculations (LOCKED)'!M13/'Formula Calculations (LOCKED)'!$M$2))) -> #DIV/0! | N13: =IF('Formula Calculations (LOCKED)'!$G13=1,((0.5*'Sheet 2. County Level Data'!$P$12)*('Formula Calculations (LOCKED)'!K13/'Formula Calculations (LOCKED)'!$K$2))+((0.5*'Sheet 2. County Level Data'!$P$12)*('Formula Calculations (LOCKED)'!R13/'Formula Calculations (LOCKED)'!$R$2)),((0.5*(10000000-'Sheet 2. County Level Data'!$P$12))*('Formula Calculations (LOCKED)'!J13/'Formula Calculations (LOCKED)'!$J$2))+((0.5*(10000000-'Sheet 2. County Level Data'!$P$12))*('Formula Calculations (LOCKED)'!Q13/'Formula Calculations (LOCKED)'!$Q$2))) -> #DIV/0!
A14: ='Sheet 2. County Level Data'!A12 -> 0 | B14: =('Formula Calculations (LOCKED)'!C14*'Sheet 2. County Level Data'!$P$4) -> #DIV/0! | C14: ='Formula Calculations (LOCKED)'!H14/'Formula Calculations (LOCKED)'!$H$2*'Sheet 2. County Level Data'!$P$4 -> #DIV/0! | D14: =('Formula Calculations (LOCKED)'!L14/'Formula Calculations (LOCKED)'!$L$2)*'Sheet 2. County Level Data'!$P$4 -> #DIV/0! | E14: =('Formula Calculations (LOCKED)'!O14/'Formula Calculations (LOCKED)'!$O$2)*'Sheet 2. County Level Data'!$P$4 -> #DIV/0! | F14: =('Formula Calculations (LOCKED)'!D14/'Formula Calculations (LOCKED)'!$D$2)*'Sheet 2. County Level Data'!$P$4 -> #DIV/0! | G14: ='Sheet 2. County Level Data'!$T$11+(0.5*10000000)*'Formula Calculations (LOCKED)'!H14/'Formula Calculations (LOCKED)'!$H$2 -> #DIV/0! | H14: =(0.5*10000000)*'Formula Calculations (LOCKED)'!H14/'Formula Calculations (LOCKED)'!$H$2+(0.5*10000000)*'Formula Calculations (LOCKED)'!D14/'Formula Calculations (LOCKED)'!$D$2 -> #DIV/0! | I14: ='Sheet 2. County Level Data'!$T$12+(0.3333333333*10000000*('Formula Calculations (LOCKED)'!H14/'Formula Calculations (LOCKED)'!$H$2))+(0.3333333333*10000000*('Formula Calculations (LOCKED)'!D14/'Formula Calculations (LOCKED)'!$D$2)) -> #DIV/0! | J14: ='Sheet 2. County Level Data'!$T$13+(0.25*10000000*('Formula Calculations (LOCKED)'!H14/'Formula Calculations (LOCKED)'!$H$2))+(0.25*10000000*('Formula Calculations (LOCKED)'!D14/'Formula Calculations (LOCKED)'!$D$2))+(0.25*10000000*('Formula Calculations (LOCKED)'!L14/'Formula Calculations (LOCKED)'!$L$2)) -> #DIV/0! | K14: ='Sheet 2. County Level Data'!$T$13+(0.25*10000000*('Formula Calculations (LOCKED)'!H14/'Formula Calculations (LOCKED)'!$H$2))+(0.25*10000000*('Formula Calculations (LOCKED)'!D14/'Formula Calculations (LOCKED)'!$D$2))+(0.25*10000000*('Formula Calculations (LOCKED)'!O14/'Formula Calculations (LOCKED)'!$O$2)) -> #DIV/0! | L14: =IF('Formula Calculations (LOCKED)'!$G14=1,('Sheet 2. County Level Data'!$P$12*('Formula Calculations (LOCKED)'!K14/'Formula Calculations (LOCKED)'!$K$2)),((10000000-'Sheet 2. County Level Data'!$P$12)*'Formula Calculations (LOCKED)'!J14/'Formula Calculations (LOCKED)'!$J$2)) -> #DIV/0! | M14: =IF('Formula Calculations (LOCKED)'!$G14=1,((0.5*'Sheet 2. County Level Data'!$P$12)*('Formula Calculations (LOCKED)'!K14/'Formula Calculations (LOCKED)'!$K$2))+((0.5*'Sheet 2. County Level Data'!$P$12)*('Formula Calculations (LOCKED)'!N14/'Formula Calculations (LOCKED)'!$N$2)),((0.5*(10000000-'Sheet 2. County Level Data'!$P$12))*('Formula Calculations (LOCKED)'!J14/'Formula Calculations (LOCKED)'!$J$2))+((0.5*(10000000-'Sheet 2. County Level Data'!$P$12))*('Formula Calculations (LOCKED)'!M14/'Formula Calculations (LOCKED)'!$M$2))) -> #DIV/0! | N14: =IF('Formula Calculations (LOCKED)'!$G14=1,((0.5*'Sheet 2. County Level Data'!$P$12)*('Formula Calculations (LOCKED)'!K14/'Formula Calculations (LOCKED)'!$K$2))+((0.5*'Sheet 2. County Level Data'!$P$12)*('Formula Calculations (LOCKED)'!R14/'Formula Calculations (LOCKED)'!$R$2)),((0.5*(10000000-'Sheet 2. County Level Data'!$P$12))*('Formula Calculations (LOCKED)'!J14/'Formula Calculations (LOCKED)'!$J$2))+((0.5*(10000000-'Sheet 2. County Level Data'!$P$12))*('Formula Calculations (LOCKED)'!Q14/'Formula Calculations (LOCKED)'!$Q$2))) -> #DIV/0!
A15: ='Sheet 2. County Level Data'!A13 -> 0 | B15: =('Formula Calculations (LOCKED)'!C15*'Sheet 2. County Level Data'!$P$4) -> #DIV/0! | C15: ='Formula Calculations (LOCKED)'!H15/'Formula Calculations (LOCKED)'!$H$2*'Sheet 2. County Level Data'!$P$4 -> #DIV/0! | D15: =('Formula Calculations (LOCKED)'!L15/'Formula Calculations (LOCKED)'!$L$2)*'Sheet 2. County Level Data'!$P$4 -> #DIV/0! | E15: =('Formula Calculations (LOCKED)'!O15/'Formula Calculations (LOCKED)'!$O$2)*'Sheet 2. County Level Data'!$P$4 -> #DIV/0! | F15: =('Formula Calculations (LOCKED)'!D15/'Formula Calculations (LOCKED)'!$D$2)*'Sheet 2. County Level Data'!$P$4 -> #DIV/0! | G15: ='Sheet 2. County Level Data'!$T$11+(0.5*10000000)*'Formula Calculations (LOCKED)'!H15/'Formula Calculations (LOCKED)'!$H$2 -> #DIV/0! | H15: =(0.5*10000000)*'Formula Calculations (LOCKED)'!H15/'Formula Calculations (LOCKED)'!$H$2+(0.5*10000000)*'Formula Calculations (LOCKED)'!D15/'Formula Calculations (LOCKED)'!$D$2 -> #DIV/0! | I15: ='Sheet 2. County Level Data'!$T$12+(0.3333333333*10000000*('Formula Calculations (LOCKED)'!H15/'Formula Calculations (LOCKED)'!$H$2))+(0.3333333333*10000000*('Formula Calculations (LOCKED)'!D15/'Formula Calculations (LOCKED)'!$D$2)) -> #DIV/0! | J15: ='Sheet 2. County Level Data'!$T$13+(0.25*10000000*('Formula Calculations (LOCKED)'!H15/'Formula Calculations (LOCKED)'!$H$2))+(0.25*10000000*('Formula Calculations (LOCKED)'!D15/'Formula Calculations (LOCKED)'!$D$2))+(0.25*10000000*('Formula Calculations (LOCKED)'!L15/'Formula Calculations (LOCKED)'!$L$2)) -> #DIV/0! | K15: ='Sheet 2. County Level Data'!$T$13+(0.25*10000000*('Formula Calculations (LOCKED)'!H15/'Formula Calculations (LOCKED)'!$H$2))+(0.25*10000000*('Formula Calculations (LOCKED)'!D15/'Formula Calculations (LOCKED)'!$D$2))+(0.25*10000000*('Formula Calculations (LOCKED)'!O15/'Formula Calculations (LOCKED)'!$O$2)) -> #DIV/0! | L15: =IF('Formula Calculations (LOCKED)'!$G15=1,('Sheet 2. County Level Data'!$P$12*('Formula Calculations (LOCKED)'!K15/'Formula Calculations (LOCKED)'!$K$2)),((10000000-'Sheet 2. County Level Data'!$P$12)*'Formula Calculations (LOCKED)'!J15/'Formula Calculations (LOCKED)'!$J$2)) -> #DIV/0! | M15: =IF('Formula Calculations (LOCKED)'!$G15=1,((0.5*'Sheet 2. County Level Data'!$P$12)*('Formula Calculations (LOCKED)'!K15/'Formula Calculations (LOCKED)'!$K$2))+((0.5*'Sheet 2. County Level Data'!$P$12)*('Formula Calculations (LOCKED)'!N15/'Formula Calculations (LOCKED)'!$N$2)),((0.5*(10000000-'Sheet 2. County Level Data'!$P$12))*('Formula Calculations (LOCKED)'!J15/'Formula Calculations (LOCKED)'!$J$2))+((0.5*(10000000-'Sheet 2. County Level Data'!$P$12))*('Formula Calculations (LOCKED)'!M15/'Formula Calculations (LOCKED)'!$M$2))) -> #DIV/0! | N15: =IF('Formula Calculations (LOCKED)'!$G15=1,((0.5*'Sheet 2. County Level Data'!$P$12)*('Formula Calculations (LOCKED)'!K15/'Formula Calculations (LOCKED)'!$K$2))+((0.5*'Sheet 2. County Level Data'!$P$12)*('Formula Calculations (LOCKED)'!R15/'Formula Calculations (LOCKED)'!$R$2)),((0.5*(10000000-'Sheet 2. County Level Data'!$P$12))*('Formula Calculations (LOCKED)'!J15/'Formula Calculations (LOCKED)'!$J$2))+((0.5*(10000000-'Sheet 2. County Level Data'!$P$12))*('Formula Calculations (LOCKED)'!Q15/'Formula Calculations (LOCKED)'!$Q$2))) -> #DIV/0!
... A162: ='Sheet 2. County Level Data'!A160 -> 0 | B162: =('Formula Calculations (LOCKED)'!C162*'Sheet 2. County Level Data'!$P$4) -> #DIV/0! | C162: ='Formula Calculations (LOCKED)'!H162/'Formula Calculations (LOCKED)'!$H$2*'Sheet 2. County Level Data'!$P$4 -> #DIV/0! | D162: =('Formula Calculations (LOCKED)'!L162/'Formula Calculations (LOCKED)'!$L$2)*'Sheet 2. County Level Data'!$P$4 -> #DIV/0! | E162: =('Formula Calculations (LOCKED)'!O162/'Formula Calculations (LOCKED)'!$O$2)*'Sheet 2. County Level Data'!$P$4 -> #DIV/0! | F162: =('Formula Calculations (LOCKED)'!D162/'Formula Calculations (LOCKED)'!$D$2)*'Sheet 2. County Level Data'!$P$4 -> #DIV/0! | G162: ='Sheet 2. County Level Data'!$T$11+(0.5*10000000)*'Formula Calculations (LOCKED)'!H162/'Formula Calculations (LOCKED)'!$H$2 -> #DIV/0! | H162: =(0.5*10000000)*'Formula Calculations (LOCKED)'!H162/'Formula Calculations (LOCKED)'!$H$2+(0.5*10000000)*'Formula Calculations (LOCKED)'!D162/'Formula Calculations (LOCKED)'!$D$2 -> #DIV/0! | I162: ='Sheet 2. County Level Data'!$T$12+(0.3333333333*10000000*('Formula Calculations (LOCKED)'!H162/'Formula Calculations (LOCKED)'!$H$2))+(0.3333333333*10000000*('Formula Calculations (LOCKED)'!D162/'Formula Calculations (LOCKED)'!$D$2)) -> #DIV/0! | J162: ='Sheet 2. County Level Data'!$T$13+(0.25*10000000*('Formula Calculations (LOCKED)'!H162/'Formula Calculations (LOCKED)'!$H$2))+(0.25*10000000*('Formula Calculations (LOCKED)'!D162/'Formula Calculations (LOCKED)'!$D$2))+(0.25*10000000*('Formula Calculations (LOCKED)'!L162/'Formula Calculations (LOCKED)'!$L$2)) -> #DIV/0! | K162: ='Sheet 2. County Level Data'!$T$13+(0.25*10000000*('Formula Calculations (LOCKED)'!H162/'Formula Calculations (LOCKED)'!$H$2))+(0.25*10000000*('Formula Calculations (LOCKED)'!D162/'Formula Calculations (LOCKED)'!$D$2))+(0.25*10000000*('Formula Calculations (LOCKED)'!O162/'Formula Calculations (LOCKED)'!$O$2)) -> #DIV/0! | L162: =IF('Formula Calculations (LOCKED)'!$G162=1,('Sheet 2. County Level Data'!$P$12*('Formula Calculations (LOCKED)'!K162/'Formula Calculations (LOCKED)'!$K$2)),((10000000-'Sheet 2. County Level Data'!$P$12)*'Formula Calculations (LOCKED)'!J162/'Formula Calculations (LOCKED)'!$J$2)) -> #DIV/0! | M162: =IF('Formula Calculations (LOCKED)'!$G162=1,((0.5*'Sheet 2. County Level Data'!$P$12)*('Formula Calculations (LOCKED)'!K162/'Formula Calculations (LOCKED)'!$K$2))+((0.5*'Sheet 2. County Level Data'!$P$12)*('Formula Calculations (LOCKED)'!N162/'Formula Calculations (LOCKED)'!$N$2)),((0.5*(10000000-'Sheet 2. County Level Data'!$P$12))*('Formula Calculations (LOCKED)'!J162/'Formula Calculations (LOCKED)'!$J$2))+((0.5*(10000000-'Sheet 2. County Level Data'!$P$12))*('Formula Calculations (LOCKED)'!M162/'Formula Calculations (LOCKED)'!$M$2))) -> #DIV/0! | N162: =IF('Formula Calculations (LOCKED)'!$G162=1,((0.5*'Sheet 2. County Level Data'!$P$12)*('Formula Calculations (LOCKED)'!K162/'Formula Calculations (LOCKED)'!$K$2))+((0.5*'Sheet 2. County Level Data'!$P$12)*('Formula Calculations (LOCKED)'!R162/'Formula Calculations (LOCKED)'!$R$2)),((0.5*(10000000-'Sheet 2. County Level Data'!$P$12))*('Formula Calculations (LOCKED)'!J162/'Formula Calculations (LOCKED)'!$J$2))+((0.5*(10000000-'Sheet 2. County Level Data'!$P$12))*('Formula Calculations (LOCKED)'!Q162/'Formula Calculations (LOCKED)'!$Q$2))) -> #DIV/0!
B163: =('Formula Calculations (LOCKED)'!C163*'Sheet 2. County Level Data'!$P$4) -> 0 | C163: ='Formula Calculations (LOCKED)'!H163/'Formula Calculations (LOCKED)'!$H$2*'Sheet 2. County Level Data'!$P$4 -> #DIV/0! | D163: =('Formula Calculations (LOCKED)'!L163/'Formula Calculations (LOCKED)'!$L$2)*'Sheet 2. County Level Data'!$P$4 -> #DIV/0! | E163: =('Formula Calculations (LOCKED)'!O163/'Formula Calculations (LOCKED)'!$O$2)*'Sheet 2. County Level Data'!$P$4 -> #DIV/0! | F163: =('Formula Calculations (LOCKED)'!D163/'Formula Calculations (LOCKED)'!$D$2)*'Sheet 2. County Level Data'!$P$4 -> #DIV/0! | L163: =IF('Formula Calculations (LOCKED)'!$G163=1,('Sheet 2. County Level Data'!$P$12*('Formula Calculations (LOCKED)'!K163/'Formula Calculations (LOCKED)'!$K$2)),((10000000-'Sheet 2. County Level Data'!$P$12)*'Formula Calculations (LOCKED)'!J163/'Formula Calculations (LOCKED)'!$J$2)) -> #DIV/0! | M163: =IF('Formula Calculations (LOCKED)'!$G163=1,((0.5*'Sheet 2. County Level Data'!$P$12)*('Formula Calculations (LOCKED)'!K163/'Formula Calculations (LOCKED)'!$K$2))+((0.5*'Sheet 2. County Level Data'!$P$12)*('Formula Calculations (LOCKED)'!N163/'Formula Calculations (LOCKED)'!$N$2)),((0.5*(10000000-'Sheet 2. County Level Data'!$P$12))*('Formula Calculations (LOCKED)'!J163/'Formula Calculations (LOCKED)'!$J$2))+((0.5*(10000000-'Sheet 2. County Level Data'!$P$12))*('Formula Calculations (LOCKED)'!M163/'Formula Calculations (LOCKED)'!$M$2))) -> #DIV/0!
B164: =('Formula Calculations (LOCKED)'!C164*'Sheet 2. County Level Data'!$P$4) -> 0 | C164: ='Formula Calculations (LOCKED)'!H164/'Formula Calculations (LOCKED)'!$H$2*'Sheet 2. County Level Data'!$P$4 -> #DIV/0! | D164: =('Formula Calculations (LOCKED)'!L164/'Formula Calculations (LOCKED)'!$L$2)*'Sheet 2. County Level Data'!$P$4 -> #DIV/0! | E164: =('Formula Calculations (LOCKED)'!O164/'Formula Calculations (LOCKED)'!$O$2)*'Sheet 2. County Level Data'!$P$4 -> #DIV/0! | F164: =('Formula Calculations (LOCKED)'!D164/'Formula Calculations (LOCKED)'!$D$2)*'Sheet 2. County Level Data'!$P$4 -> #DIV/0! | L164: =IF('Formula Calculations (LOCKED)'!$G164=1,('Sheet 2. County Level Data'!$P$12*('Formula Calculations (LOCKED)'!K164/'Formula Calculations (LOCKED)'!$K$2)),((10000000-'Sheet 2. County Level Data'!$P$12)*'Formula Calculations (LOCKED)'!J164/'Formula Calculations (LOCKED)'!$J$2)) -> #DIV/0! | M164: =IF('Formula Calculations (LOCKED)'!$G164=1,((0.5*'Sheet 2. County Level Data'!$P$12)*('Formula Calculations (LOCKED)'!K164/'Formula Calculations (LOCKED)'!$K$2))+((0.5*'Sheet 2. County Level Data'!$P$12)*('Formula Calculations (LOCKED)'!N164/'Formula Calculations (LOCKED)'!$N$2)),((0.5*(10000000-'Sheet 2. County Level Data'!$P$12))*('Formula Calculations (LOCKED)'!J164/'Formula Calculations (LOCKED)'!$J$2))+((0.5*(10000000-'Sheet 2. County Level Data'!$P$12))*('Formula Calculations (LOCKED)'!M164/'Formula Calculations (LOCKED)'!$M$2))) -> #DIV/0!
B165: =('Formula Calculations (LOCKED)'!C165*'Sheet 2. County Level Data'!$P$4) -> 0 | C165: ='Formula Calculations (LOCKED)'!H165/'Formula Calculations (LOCKED)'!$H$2*'Sheet 2. County Level Data'!$P$4 -> #DIV/0! | D165: =('Formula Calculations (LOCKED)'!L165/'Formula Calculations (LOCKED)'!$L$2)*'Sheet 2. County Level Data'!$P$4 -> #DIV/0! | E165: =('Formula Calculations (LOCKED)'!O165/'Formula Calculations (LOCKED)'!$O$2)*'Sheet 2. County Level Data'!$P$4 -> #DIV/0! | F165: =('Formula Calculations (LOCKED)'!D165/'Formula Calculations (LOCKED)'!$D$2)*'Sheet 2. County Level Data'!$P$4 -> #DIV/0! | L165: =IF('Formula Calculations (LOCKED)'!$G165=1,('Sheet 2. County Level Data'!$P$12*('Formula Calculations (LOCKED)'!K165/'Formula Calculations (LOCKED)'!$K$2)),((10000000-'Sheet 2. County Level Data'!$P$12)*'Formula Calculations (LOCKED)'!J165/'Formula Calculations (LOCKED)'!$J$2)) -> #DIV/0! | M165: =IF('Formula Calculations (LOCKED)'!$G165=1,((0.5*'Sheet 2. County Level Data'!$P$12)*('Formula Calculations (LOCKED)'!K165/'Formula Calculations (LOCKED)'!$K$2))+((0.5*'Sheet 2. County Level Data'!$P$12)*('Formula Calculations (LOCKED)'!N165/'Formula Calculations (LOCKED)'!$N$2)),((0.5*(10000000-'Sheet 2. County Level Data'!$P$12))*('Formula Calculations (LOCKED)'!J165/'Formula Calculations (LOCKED)'!$J$2))+((0.5*(10000000-'Sheet 2. County Level Data'!$P$12))*('Formula Calculations (LOCKED)'!M165/'Formula Calculations (LOCKED)'!$M$2))) -> #DIV/0!
B166: =('Formula Calculations (LOCKED)'!C166*'Sheet 2. County Level Data'!$P$4) -> 0 | C166: ='Formula Calculations (LOCKED)'!H166/'Formula Calculations (LOCKED)'!$H$2*'Sheet 2. County Level Data'!$P$4 -> #DIV/0! | D166: =('Formula Calculations (LOCKED)'!L166/'Formula Calculations (LOCKED)'!$L$2)*'Sheet 2. County Level Data'!$P$4 -> #DIV/0! | E166: =('Formula Calculations (LOCKED)'!O166/'Formula Calculations (LOCKED)'!$O$2)*'Sheet 2. County Level Data'!$P$4 -> #DIV/0! | F166: =('Formula Calculations (LOCKED)'!D166/'Formula Calculations (LOCKED)'!$D$2)*'Sheet 2. County Level Data'!$P$4 -> #DIV/0! | L166: =IF('Formula Calculations (LOCKED)'!$G166=1,('Sheet 2. County Level Data'!$P$12*('Formula Calculations (LOCKED)'!K166/'Formula Calculations (LOCKED)'!$K$2)),((10000000-'Sheet 2. County Level Data'!$P$12)*'Formula Calculations (LOCKED)'!J166/'Formula Calculations (LOCKED)'!$J$2)) -> #DIV/0! | M166: =IF('Formula Calculations (LOCKED)'!$G166=1,((0.5*'Sheet 2. County Level Data'!$P$12)*('Formula Calculations (LOCKED)'!K166/'Formula Calculations (LOCKED)'!$K$2))+((0.5*'Sheet 2. County Level Data'!$P$12)*('Formula Calculations (LOCKED)'!N166/'Formula Calculations (LOCKED)'!$N$2)),((0.5*(10000000-'Sheet 2. County Level Data'!$P$12))*('Formula Calculations (LOCKED)'!J166/'Formula Calculations (LOCKED)'!$J$2))+((0.5*(10000000-'Sheet 2. County Level Data'!$P$12))*('Formula Calculations (LOCKED)'!M166/'Formula Calculations (LOCKED)'!$M$2))) -> #DIV/0!
B167: =('Formula Calculations (LOCKED)'!C167*'Sheet 2. County Level Data'!$P$4) -> 0 | C167: ='Formula Calculations (LOCKED)'!H167/'Formula Calculations (LOCKED)'!$H$2*'Sheet 2. County Level Data'!$P$4 -> #DIV/0! | D167: =('Formula Calculations (LOCKED)'!L167/'Formula Calculations (LOCKED)'!$L$2)*'Sheet 2. County Level Data'!$P$4 -> #DIV/0! | E167: =('Formula Calculations (LOCKED)'!O167/'Formula Calculations (LOCKED)'!$O$2)*'Sheet 2. County Level Data'!$P$4 -> #DIV/0! | F167: =('Formula Calculations (LOCKED)'!D167/'Formula Calculations (LOCKED)'!$D$2)*'Sheet 2. County Level Data'!$P$4 -> #DIV/0! | L167: =IF('Formula Calculations (LOCKED)'!$G167=1,('Sheet 2. County Level Data'!$P$12*('Formula Calculations (LOCKED)'!K167/'Formula Calculations (LOCKED)'!$K$2)),((10000000-'Sheet 2. County Level Data'!$P$12)*'Formula Calculations (LOCKED)'!J167/'Formula Calculations (LOCKED)'!$J$2)) -> #DIV/0! | M167: =IF('Formula Calculations (LOCKED)'!$G167=1,((0.5*'Sheet 2. County Level Data'!$P$12)*('Formula Calculations (LOCKED)'!K167/'Formula Calculations (LOCKED)'!$K$2))+((0.5*'Sheet 2. County Level Data'!$P$12)*('Formula Calculations (LOCKED)'!N167/'Formula Calculations (LOCKED)'!$N$2)),((0.5*(10000000-'Sheet 2. County Level Data'!$P$12))*('Formula Calculations (LOCKED)'!J167/'Formula Calculations (LOCKED)'!$J$2))+((0.5*(10000000-'Sheet 2. County Level Data'!$P$12))*('Formula Calculations (LOCKED)'!M167/'Formula Calculations (LOCKED)'!$M$2))) -> #DIV/0!
B168: =('Formula Calculations (LOCKED)'!C168*'Sheet 2. County Level Data'!$P$4) -> 0 | C168: ='Formula Calculations (LOCKED)'!H168/'Formula Calculations (LOCKED)'!$H$2*'Sheet 2. County Level Data'!$P$4 -> #DIV/0! | D168: =('Formula Calculations (LOCKED)'!L168/'Formula Calculations (LOCKED)'!$L$2)*'Sheet 2. County Level Data'!$P$4 -> #DIV/0! | E168: =('Formula Calculations (LOCKED)'!O168/'Formula Calculations (LOCKED)'!$O$2)*'Sheet 2. County Level Data'!$P$4 -> #DIV/0! | F168: =('Formula Calculations (LOCKED)'!D168/'Formula Calculations (LOCKED)'!$D$2)*'Sheet 2. County Level Data'!$P$4 -> #DIV/0! | L168: =IF('Formula Calculations (LOCKED)'!$G168=1,('Sheet 2. County Level Data'!$P$12*('Formula Calculations (LOCKED)'!K168/'Formula Calculations (LOCKED)'!$K$2)),((10000000-'Sheet 2. County Level Data'!$P$12)*'Formula Calculations (LOCKED)'!J168/'Formula Calculations (LOCKED)'!$J$2)) -> #DIV/0! | M168: =IF('Formula Calculations (LOCKED)'!$G168=1,((0.5*'Sheet 2. County Level Data'!$P$12)*('Formula Calculations (LOCKED)'!K168/'Formula Calculations (LOCKED)'!$K$2))+((0.5*'Sheet 2. County Level Data'!$P$12)*('Formula Calculations (LOCKED)'!N168/'Formula Calculations (LOCKED)'!$N$2)),((0.5*(10000000-'Sheet 2. County Level Data'!$P$12))*('Formula Calculations (LOCKED)'!J168/'Formula Calculations (LOCKED)'!$J$2))+((0.5*(10000000-'Sheet 2. County Level Data'!$P$12))*('Formula Calculations (LOCKED)'!M168/'Formula Calculations (LOCKED)'!$M$2))) -> #DIV/0!
B169: =('Formula Calculations (LOCKED)'!C169*'Sheet 2. County Level Data'!$P$4) -> 0 | C169: ='Formula Calculations (LOCKED)'!H169/'Formula Calculations (LOCKED)'!$H$2*'Sheet 2. County Level Data'!$P$4 -> #DIV/0! | D169: =('Formula Calculations (LOCKED)'!L169/'Formula Calculations (LOCKED)'!$L$2)*'Sheet 2. County Level Data'!$P$4 -> #DIV/0! | E169: =('Formula Calculations (LOCKED)'!O169/'Formula Calculations (LOCKED)'!$O$2)*'Sheet 2. County Level Data'!$P$4 -> #DIV/0! | F169: =('Formula Calculations (LOCKED)'!D169/'Formula Calculations (LOCKED)'!$D$2)*'Sheet 2. County Level Data'!$P$4 -> #DIV/0! | L169: =IF('Formula Calculations (LOCKED)'!$G169=1,('Sheet 2. County Level Data'!$P$12*('Formula Calculations (LOCKED)'!K169/'Formula Calculations (LOCKED)'!$K$2)),((10000000-'Sheet 2. County Level Data'!$P$12)*'Formula Calculations (LOCKED)'!J169/'Formula Calculations (LOCKED)'!$J$2)) -> #DIV/0! | M169: =IF('Formula Calculations (LOCKED)'!$G169=1,((0.5*'Sheet 2. County Level Data'!$P$12)*('Formula Calculations (LOCKED)'!K169/'Formula Calculations (LOCKED)'!$K$2))+((0.5*'Sheet 2. County Level Data'!$P$12)*('Formula Calculations (LOCKED)'!N169/'Formula Calculations (LOCKED)'!$N$2)),((0.5*(10000000-'Sheet 2. County Level Data'!$P$12))*('Formula Calculations (LOCKED)'!J169/'Formula Calculations (LOCKED)'!$J$2))+((0.5*(10000000-'Sheet 2. County Level Data'!$P$12))*('Formula Calculations (LOCKED)'!M169/'Formula Calculations (LOCKED)'!$M$2))) -> #DIV/0!
B170: =('Formula Calculations (LOCKED)'!C170*'Sheet 2. County Level Data'!$P$4) -> 0 | C170: ='Formula Calculations (LOCKED)'!H170/'Formula Calculations (LOCKED)'!$H$2*'Sheet 2. County Level Data'!$P$4 -> #DIV/0! | D170: =('Formula Calculations (LOCKED)'!L170/'Formula Calculations (LOCKED)'!$L$2)*'Sheet 2. County Level Data'!$P$4 -> #DIV/0! | E170: =('Formula Calculations (LOCKED)'!O170/'Formula Calculations (LOCKED)'!$O$2)*'Sheet 2. County Level Data'!$P$4 -> #DIV/0! | F170: =('Formula Calculations (LOCKED)'!D170/'Formula Calculations (LOCKED)'!$D$2)*'Sheet 2. County Level Data'!$P$4 -> #DIV/0! | L170: =IF('Formula Calculations (LOCKED)'!$G170=1,('Sheet 2. County Level Data'!$P$12*('Formula Calculations (LOCKED)'!K170/'Formula Calculations (LOCKED)'!$K$2)),((10000000-'Sheet 2. County Level Data'!$P$12)*'Formula Calculations (LOCKED)'!J170/'Formula Calculations (LOCKED)'!$J$2)) -> #DIV/0! | M170: =IF('Formula Calculations (LOCKED)'!$G170=1,((0.5*'Sheet 2. County Level Data'!$P$12)*('Formula Calculations (LOCKED)'!K170/'Formula Calculations (LOCKED)'!$K$2))+((0.5*'Sheet 2. County Level Data'!$P$12)*('Formula Calculations (LOCKED)'!N170/'Formula Calculations (LOCKED)'!$N$2)),((0.5*(10000000-'Sheet 2. County Level Data'!$P$12))*('Formula Calculations (LOCKED)'!J170/'Formula Calculations (LOCKED)'!$J$2))+((0.5*(10000000-'Sheet 2. County Level Data'!$P$12))*('Formula Calculations (LOCKED)'!M170/'Formula Calculations (LOCKED)'!$M$2))) -> #DIV/0!
B171: =('Formula Calculations (LOCKED)'!C171*'Sheet 2. County Level Data'!$P$4) -> 0 | C171: ='Formula Calculations (LOCKED)'!H171/'Formula Calculations (LOCKED)'!$H$2*'Sheet 2. County Level Data'!$P$4 -> #DIV/0! | D171: =('Formula Calculations (LOCKED)'!L171/'Formula Calculations (LOCKED)'!$L$2)*'Sheet 2. County Level Data'!$P$4 -> #DIV/0! | E171: =('Formula Calculations (LOCKED)'!O171/'Formula Calculations (LOCKED)'!$O$2)*'Sheet 2. County Level Data'!$P$4 -> #DIV/0! | F171: =('Formula Calculations (LOCKED)'!D171/'Formula Calculations (LOCKED)'!$D$2)*'Sheet 2. County Level Data'!$P$4 -> #DIV/0! | L171: =IF('Formula Calculations (LOCKED)'!$G171=1,('Sheet 2. County Level Data'!$P$12*('Formula Calculations (LOCKED)'!K171/'Formula Calculations (LOCKED)'!$K$2)),((10000000-'Sheet 2. County Level Data'!$P$12)*'Formula Calculations (LOCKED)'!J171/'Formula Calculations (LOCKED)'!$J$2)) -> #DIV/0! | M171: =IF('Formula Calculations (LOCKED)'!$G171=1,((0.5*'Sheet 2. County Level Data'!$P$12)*('Formula Calculations (LOCKED)'!K171/'Formula Calculations (LOCKED)'!$K$2))+((0.5*'Sheet 2. County Level Data'!$P$12)*('Formula Calculations (LOCKED)'!N171/'Formula Calculations (LOCKED)'!$N$2)),((0.5*(10000000-'Sheet 2. County Level Data'!$P$12))*('Formula Calculations (LOCKED)'!J171/'Formula Calculations (LOCKED)'!$J$2))+((0.5*(10000000-'Sheet 2. County Level Data'!$P$12))*('Formula Calculations (LOCKED)'!M171/'Formula Calculations (LOCKED)'!$M$2))) -> #DIV/0!
B172: =('Formula Calculations (LOCKED)'!C172*'Sheet 2. County Level Data'!$P$4) -> 0 | C172: ='Formula Calculations (LOCKED)'!H172/'Formula Calculations (LOCKED)'!$H$2*'Sheet 2. County Level Data'!$P$4 -> #DIV/0! | D172: =('Formula Calculations (LOCKED)'!L172/'Formula Calculations (LOCKED)'!$L$2)*'Sheet 2. County Level Data'!$P$4 -> #DIV/0! | E172: =('Formula Calculations (LOCKED)'!O172/'Formula Calculations (LOCKED)'!$O$2)*'Sheet 2. County Level Data'!$P$4 -> #DIV/0! | F172: =('Formula Calculations (LOCKED)'!D172/'Formula Calculations (LOCKED)'!$D$2)*'Sheet 2. County Level Data'!$P$4 -> #DIV/0! | L172: =IF('Formula Calculations (LOCKED)'!$G172=1,('Sheet 2. County Level Data'!$P$12*('Formula Calculations (LOCKED)'!K172/'Formula Calculations (LOCKED)'!$K$2)),((10000000-'Sheet 2. County Level Data'!$P$12)*'Formula Calculations (LOCKED)'!J172/'Formula Calculations (LOCKED)'!$J$2)) -> #DIV/0! | M172: =IF('Formula Calculations (LOCKED)'!$G172=1,((0.5*'Sheet 2. County Level Data'!$P$12)*('Formula Calculations (LOCKED)'!K172/'Formula Calculations (LOCKED)'!$K$2))+((0.5*'Sheet 2. County Level Data'!$P$12)*('Formula Calculations (LOCKED)'!N172/'Formula Calculations (LOCKED)'!$N$2)),((0.5*(10000000-'Sheet 2. County Level Data'!$P$12))*('Formula Calculations (LOCKED)'!J172/'Formula Calculations (LOCKED)'!$J$2))+((0.5*(10000000-'Sheet 2. County Level Data'!$P$12))*('Formula Calculations (LOCKED)'!M172/'Formula Calculations (LOCKED)'!$M$2))) -> #DIV/0!
